❌ Connection failed: {'message': 'Credenciales inválidas'}
Traceback (most recent call last):
  File "C:\EndpointPython\app.py", line 41, in <module>
    sio.connect("http://socket-handle-tests.amaditaplayground.com:30008", transports=["websocket"])
    ~~~~~~~~~~~^^^^^^^^^^^^^^^^^^^^^^^^^^^^^^^^^^^^^^^^^^^^^^^^^^^^^^^^^^^^^^^^^^^^^^^^^^^^^^^^^^^^
  File "C:\EndpointPython\venv\Lib\site-packages\socketio\client.py", line 168, in connect
    raise exceptions.ConnectionError(
        'One or more namespaces failed to connect')
socketio.exceptions.ConnectionError: One or more namespaces failed to connect
